Workbook

Sheet README
A1: README — what each tab does, who owns it, and how to fill it
A2: VSYST CMO Workbook · version 1.0 · built 2026-08-27 · companion to CMO-Docs. Grey italic on pale yellow = illustrative example data, overwrite it. Pale blue = a live formula, do not type over it. Pale green = a cell you are meant to type into. Import to Google Sheets: File → Import → Upload → Replace spreadsheet, then re-check the formulas on the CAC & Payback and Pipeline tabs.
A4: # | B4: Tab | C4: What it does | D4: Key formulas / how to fill | E4: Owner · cadence
A5: 1 | B5: README | C5: This page: tab guide, colour legend, the VERIFY LIVE rule, Google Sheets import note. | D5: Read the legend below before touching anything. Every tab names the toolkit template it comes from. | E5: CEO · on every version bump
A6: 2 | B6: Target List | C6: The Raipur 100 — a hundred NAMED pumps with a route to an introduction. Template M03. It is the denominator for HC3 (~60% of ICP pumps within 60 km) and the source of every row in Pipeline. | D6: Score the four rubric factors 1–5 in columns J–M; Priority score (N) = J×3 + K×2 + L×2 + M×3, max 50. Priority band (O) computes A ≥38 · B 26–37 · C ≤25. No row without an owner's name; no row without a dated next action. | E6: Domain director · 30 rows in Week 1, 100 by Week 4, groomed every Monday
A7: 3 | B7: Pipeline | C7: Every named pump's stage, next action and objection. Template M07. Nine stages, each with an exit test; the conversion block computes your own funnel rates off your own rows. | D7: Stage is a dropdown — do not add a stage. Days since last touch (G) = TODAY() − Last touch; over 14 days turns red and gets a decision on Monday. The conversion block counts rows that REACHED each stage, so it reads a snapshot correctly. | E7: Domain director · same evening as every visit; reviewed Monday 10 min
A8: 4 | B8: Marketing Scorecard | C8: The eight weekly marketing numbers (HC8), thirteen weeks trailing. Template M13 §A. Deliberately the same shape as the COO's T05 KPI Scorecard. | D8: Fill weeks left to right with no gaps. Last (V) = last filled week; Trend (W) compares it with the week before; Status (X) computes Green/Amber/Red from Direction, Goal and Red line. Eight rows, no more. | E8: One named owner per row · Monday by 09:30
A9: 5 | B9: CAC & Payback | C9: What each channel actually cost, per paying dealer, and how many months of gross profit it takes to earn it back. Template M13 §B–D. | D9: Total channel cost = cash + founder hours × imputed ₹/hour + travel. CAC = total ÷ new paying dealers. Payback = CAC ÷ (ARPA × gross margin), plus any free months given. Blended CAC is a sanity check, never a decision. | E9: CEO · rows quarterly, review the first Monday monthly
A10: 6 | B10: Campaign Budget | C10: One campaign on one page: brief, budget planned vs actual, the weekly log, the post-mortem and the multi-district block. Template M12. Filled here with the Raipur 100 example. | D10: Variance ₹ = actual − planned (positive is overspend, and turns red). The weekly log totals itself. Post-mortem CAC = spend ÷ activated. The T+30 district gate computes Go ≥5 · Watch 3–4 · Stop <3. | E10: Third director · one brief per campaign; log Monday 09:30; post-mortem within 5 days
A11: 7 | B11: Content Calendar | C11: One piece a week — what, who shoots it, who edits it, where it went, and whether it earned a reply. Template M11 §D. | D11: Reply rate = replies within 48h ÷ recipients; it is scorecard row 7. The 4-week rate at the bottom is Σ replies ÷ Σ recipients, not an average of percentages. Zero replies twice = the row is deleted, not debated. | E11: CEO (site) · domain director (WhatsApp, shoots) · third director (edits) · row filled Friday, broadcast Tuesday
A12: 8 | B12: Referral Tracker | C12: Every Dealer Dost ask, including the ones that failed, and what is owed. Template M09 §C. | D12: Reward due (₹) computes from Stage: ₹0 until Live, ₹2,000 at Live, ₹5,000 once they are Paying in month 3 — all VERIFY LIVE against the signed tier sheet. Totals block flags the ₹20,000/year §194R TDS line. | E12: Domain director · logged the same day; reviewed Friday, 30 min
A13: 9 | B13: Channel Experiments | C13: One channel, two weeks, one number, a verdict. Lesson 05 §6, reviewed monthly per lesson 11 §7. | D13: Total cost = cash + hours × the imputed rate on CAC & Payback + travel. CAC = total cost ÷ paying dealers. Kill line is written BEFORE the start date; the verdict cell stays empty until the end date. | E13: Third director · one row per experiment; verdict on the end date
A15: Colour legend
B16: Illustrative example — grey italic on pale yellow. Every one of these rows is fictional: invented pumps, invented owners, invented numbers. Overwrite them; they are there to show the shape.
B17: Computed cell — a live formula. Do not type over it.
B18: Input cell — this is where you type.
B19: Section band — a heading inside the sheet.
A21: VERIFY LIVE
A22: Every rupee figure in this workbook is illustrative or was true on 2026-08-27. The plan tiers (₹599 / ₹1,799 / ₹4,999 + Enterprise, ex-GST, per GSTIN, billing web-only, 14-day no-card trial) are UNDER OWNER SIGN-OFF — never quote them as final, and never quote the older ₹999–2,499 hybrid numbers. The ₹400/hour imputed founder rate, the ₹2,000 / ₹3,000 Dealer Dost bounties, the ₹30–50k monthly envelope, the WhatsApp per-message rates and every CAC, goal and red line on these tabs are VERIFY LIVE: confirm with the CEO (pricing), the CA (TDS §194R, GST on WhatsApp fees) or the BSP (message rates) before a decision turns on them.
A24: Where a tab differs from its template: Target List splits M03's 'Location · km' and 'Next action + date' into separate columns and adds the four rubric factor columns the score is computed from; Pipeline splits M07's 'Next action + date' and 'Referral asked?' the same way and adds a computed 'Days since last touch'; Content Calendar splits M11's 'Replies / Views @48h' into recipients, replies, computed reply rate and views. Nothing else was added, removed or reordered.

Sheet Target List
A1: Target List — the Raipur 100, named, scored and routed to an introduction
A2: Fills M03 and exercise 8.3 in lesson 03. A row is a pump, not a company. No row without the owner's name; no row without a dated next action. Estimated fields carry 'est.' until the first visit. Disqualified rows stay, status DQ, with a re-look date. Re-score after every visit — pump #3 changes pump #11.
A4: A. The list — 100 named pumps within 60 km of Raipur
A5: Pump name | B5: OMC | C5: Location | D5: km from Raipur | E5: Owner name | F5: Second-gen? | G5: Est. B2B credit customers | H5: Credit volume band | I5: Intro path (who introduces us, by name) | J5: Credit volume 1-5 (×3) | K5: Second-gen 1-5 (×2) | L5: Distance 1-5 (×2) | M5: Intro strength 1-5 (×3) | N5: Priority score /50 | O5: Priority band | P5: Status | Q5: Next action | R5: Next date | S5: Owner (ours)
A6: Maa Danteshwari Fuels (fictional) | B6: IOCL | C6: Tatibandh | D6: 8 | E6: R. Verma | F6: Y | G6: 24 est. | H6: A | I6: Domain director — school friend | J6: 5 | K6: 5 | L6: 5 | M6: 5 | N6: =IF(COUNT(J6:M6)<4,"",J6*3+K6*2+L6*2+M6*3) | O6: =IF(N6="","",IF(N6>=38,"A",IF(N6>=26,"B","C"))) | P6: Intro requested | Q6: Call Verma-ji, ask for a Tuesday slot | R6: 46267 | S6: Domain dir.
A7: Highway Auto Centre (fictional) | B7: BPCL | C7: NH-53, Kharora | D7: 34 | E7: S. Sahu | F7: Y | G7: 30 est. | H7: A | I7: Transporter who fuels there | J7: 5 | K7: 5 | L7: 3 | M7: 3 | N7: =IF(COUNT(J7:M7)<4,"",J7*3+K7*2+L7*2+M7*3) | O7: =IF(N7="","",IF(N7>=38,"A",IF(N7>=26,"B","C"))) | P7: New | Q7: Visit on the Kharora cluster run | R7: 46270 | S7: Domain dir.
A8: Shree Balaji Filling (fictional) | B8: HPCL | C8: Bhanpuri | D8: 11 | E8: M. Agrawal | F8: N | G8: 12 est. | H8: B | I8: Our CA handles his books | J8: 3 | K8: 1 | L8: 5 | M8: 3 | N8: =IF(COUNT(J8:M8)<4,"",J8*3+K8*2+L8*2+M8*3) | O8: =IF(N8="","",IF(N8>=38,"A",IF(N8>=26,"B","C"))) | P8: Researching | Q8: CA to introduce over WhatsApp | R8: 46268 | S8: CEO
A9: Ring Road Fuels (fictional) | B9: IOCL | C9: Ring Road 2 | D9: 6 | E9: K. Dewangan | F9: unknown | G9: 4 est. | H9: C | I9: none yet | J9: 1 | K9: 2 | L9: 5 | M9: 1 | N9: =IF(COUNT(J9:M9)<4,"",J9*3+K9*2+L9*2+M9*3) | O9: =IF(N9="","",IF(N9>=38,"A",IF(N9>=26,"B","C"))) | P9: New | Q9: Walk-in during the Tatibandh cluster run | R9: 46274 | S9: Third dir.
A10: City Point Petroleum (fictional) | B10: BPCL | C10: Pandri | D10: 4 | E10: (manager-run, owner in Dubai) | F10: N | G10: 0 | H10: C | I10: — | J10: 1 | K10: 1 | L10: 5 | M10: 1 | N10: =IF(COUNT(J10:M10)<4,"",J10*3+K10*2+L10*2+M10*3) | O10: =IF(N10="","",IF(N10>=38,"A",IF(N10>=26,"B","C"))) | P10: DQ | Q10: Re-look — owner may return | R10: 46447 | S10: —
N11: =IF(COUNT(J11:M11)<4,"",J11*3+K11*2+L11*2+M11*3) | O11: =IF(N11="","",IF(N11>=38,"A",IF(N11>=26,"B","C")))
N12: =IF(COUNT(J12:M12)<4,"",J12*3+K12*2+L12*2+M12*3) | O12: =IF(N12="","",IF(N12>=38,"A",IF(N12>=26,"B","C")))
N13: =IF(COUNT(J13:M13)<4,"",J13*3+K13*2+L13*2+M13*3) | O13: =IF(N13="","",IF(N13>=38,"A",IF(N13>=26,"B","C")))
N14: =IF(COUNT(J14:M14)<4,"",J14*3+K14*2+L14*2+M14*3) | O14: =IF(N14="","",IF(N14>=38,"A",IF(N14>=26,"B","C")))
N15: =IF(COUNT(J15:M15)<4,"",J15*3+K15*2+L15*2+M15*3) | O15: =IF(N15="","",IF(N15>=38,"A",IF(N15>=26,"B","C")))
N16: =IF(COUNT(J16:M16)<4,"",J16*3+K16*2+L16*2+M16*3) | O16: =IF(N16="","",IF(N16>=38,"A",IF(N16>=26,"B","C")))
N17: =IF(COUNT(J17:M17)<4,"",J17*3+K17*2+L17*2+M17*3) | O17: =IF(N17="","",IF(N17>=38,"A",IF(N17>=26,"B","C")))
N18: =IF(COUNT(J18:M18)<4,"",J18*3+K18*2+L18*2+M18*3) | O18: =IF(N18="","",IF(N18>=38,"A",IF(N18>=26,"B","C")))
N19: =IF(COUNT(J19:M19)<4,"",J19*3+K19*2+L19*2+M19*3) | O19: =IF(N19="","",IF(N19>=38,"A",IF(N19>=26,"B","C")))
N20: =IF(COUNT(J20:M20)<4,"",J20*3+K20*2+L20*2+M20*3) | O20: =IF(N20="","",IF(N20>=38,"A",IF(N20>=26,"B","C")))
N21: =IF(COUNT(J21:M21)<4,"",J21*3+K21*2+L21*2+M21*3) | O21: =IF(N21="","",IF(N21>=38,"A",IF(N21>=26,"B","C")))
N22: =IF(COUNT(J22:M22)<4,"",J22*3+K22*2+L22*2+M22*3) | O22: =IF(N22="","",IF(N22>=38,"A",IF(N22>=26,"B","C")))
... N45: =IF(COUNT(J45:M45)<4,"",J45*3+K45*2+L45*2+M45*3) | O45: =IF(N45="","",IF(N45>=38,"A",IF(N45>=26,"B","C")))
A47: B. The scoring rubric — four factors, weighted, maximum 50
A48: Factor | B48: Weight | C48: 5 | D48: 3 | E48: 1 | Q48: Rule
A49: B2B credit volume | B49: ×3 | C49: 20+ credit customers, band A | D49: 8–15 customers, band B | E49: Cash/UPI only | Q49: The one factor worth arguing about — it is the whole reason he would pay
A50: Second-generation presence | B50: ×2 | C50: Son/daughter running operations | D50: Involved but not deciding | E50: Owner 65+, nobody younger | Q50: The son influences; the father signs (HC5)
A51: Distance from Raipur | B51: ×2 | C51: ≤20 km | D51: 21–40 km | E51: 60 km+ | Q51: Straight-line km; drives the cluster you visit in one morning
A52: Intro path strength | B52: ×3 | C52: The domain director knows him | D52: A CA or association contact | E52: None yet | Q52: The one column nobody can scrape
A54: Bands | B54: A ≥ 38 | C54: B 26–37 | D54: C ≤ 25 | E54: Work A first, in geographic clusters, so one morning covers four pumps.
A56: C. Monday grooming — 20 minutes before the ops meeting
A57: Check | B57: Count | C57: Rule
A58: Rows on the list | B58: =SUMPRODUCT(1*(A6:A45<>"")) | C58: 30 by Week 1, 100 by Week 4. HC3 needs ~60% of ICP pumps within 60 km, and you cannot claim a percentage without a count.
A59: Band A rows | B59: =COUNTIF(O6:O45,"A") | C59: These are this week's visits. Cluster them geographically.
A60: Band B rows | B60: =COUNTIF(O6:O45,"B") | C60: Worked after the A rows, or when a cluster run passes the door.
A61: Band C rows | B61: =COUNTIF(O6:O45,"C") | C61: Not visits. To visit one, change a factor score and say which.
A62: Rows with no owner name | B62: =SUMPRODUCT((A6:A45<>"")*(E6:E45="")) | C62: An address is not a lead. Must be zero before scoring.
A63: Rows with no dated next action | B63: =SUMPRODUCT((A6:A45<>"")*(R6:R45="")) | C63: No date, no action, row is dead.
A64: Next actions past due | B64: =SUMPRODUCT((R6:R45<>"")*(R6:R45<TODAY())) | C64: Every one gets a new date or the row becomes DQ on Monday.
A65: Disqualified (DQ) | B65: =COUNTIF(P6:P45,"DQ") | C65: DQ rows STAY, with a re-look date — or you research them again in three months.
A67: Scores on the five example rows are computed strictly from the rubric above, so they differ by a few points from the illustrative totals printed in M03's worked-example table (that table's numbers were written by hand and are not reproducible from its own rubric — 47/42/34/21/12 there, 50/40/30/20/18 here). The ranking, which is the point of the sheet, is identical. Sources for building the list: IOCL / BPCL / HPCL outlet locators, PPAC's state-wise retail-outlet file, association rolls, hardware service engineers, and the domain director's phone — see M03.

Sheet Pipeline
A1: Pipeline — every named pump, its stage, its next action and the objection actually blocking it
A2: Fills M07 and lesson 06. Nine stages, each with an exit test (section B) — do not add a stage. A stage moves only on its exit test; a cold row becomes Lost with a reason, never quietly Demoed again. Objections are recorded VERBATIM, in his language — a paraphrase feeds nothing back into M05. Plan / tier and MRR are VERIFY LIVE, owner sign-off pending.
A4: A. The pipeline
A5: Pump | B5: Owner (dealer) | C5: Segment | D5: Source channel | E5: Stage | F5: Last touch | G5: Days since last touch | H5: Next action (a verb and a name) | I5: Next date | J5: Objection heard (verbatim) | K5: Trial start | L5: Activation date | M5: Plan / tier | N5: MRR ₹ | O5: Referral asked? | P5: Referral asked on | Q5: Owner (ours)
A6: Maa Danteshwari Fuels | B6: R. Verma | C6: pump dealer | D6: referral | E6: Paying | F6: 46259 | G6: =IF(F6="","",TODAY()-F6) | H6: Activation check at his month-end — Domain dir. | I6: 46263 | J6: — | K6: 46239 | M6: ₹1,799 | N6: 1799 | O6: Y | P6: 46259 | Q6: Domain dir.
A7: Highway Auto Centre | B7: S. Sahu | C7: pump dealer | D7: OMC TM | E7: Trial started | F7: 46260 | G7: =IF(F7="","",TODAY()-F7) | H7: Day-14 meeting with the munim present — Domain dir. | I7: 46274 | J7: "munim ko sikhana padega" | K7: 46260 | M7: — | O7: N | Q7: Domain dir.
A8: Shree Balaji Filling | B8: M. Agrawal | C8: pump dealer | D8: CA | E8: Demoed | F8: 46255 | G8: =IF(F8="","",TODAY()-F8) | H8: Re-demo with the son present — CEO | I8: 46267 | J8: "beta dekhega" | M8: — | O8: N | Q8: CEO
A9: Ring Road Fuels | B9: K. Dewangan | C9: pump dealer | D9: field visit | E9: Visited | F9: 46242 | G9: =IF(F9="","",TODAY()-F9) | J9: "abhi Tally theek hai" | M9: — | O9: N | Q9: Third dir.
A10: City Point Petroleum | B10: (manager-run) | C10: pump dealer | D10: field visit | E10: Lost | F10: 46238 | G10: =IF(F10="","",TODAY()-F10) | H10: — | J10: "malik Dubai mein hain" | M10: — | O10: N | Q10: —
G11: =IF(F11="","",TODAY()-F11)
G12: =IF(F12="","",TODAY()-F12)
G13: =IF(F13="","",TODAY()-F13)
G14: =IF(F14="","",TODAY()-F14)
G15: =IF(F15="","",TODAY()-F15)
G16: =IF(F16="","",TODAY()-F16)
G17: =IF(F17="","",TODAY()-F17)
G18: =IF(F18="","",TODAY()-F18)
G19: =IF(F19="","",TODAY()-F19)
G20: =IF(F20="","",TODAY()-F20)
G21: =IF(F21="","",TODAY()-F21)
G22: =IF(F22="","",TODAY()-F22)
... G50: =IF(F50="","",TODAY()-F50)
A52: B. Stages and exit tests — a stage moves only on its checkable event
A53: Stage | B53: Exit test — the checkable event | Q53: Rows here now
A54: Target | B54: Named pump, owner, phone, source, ICP score in the Target List tab | Q54: =COUNTIF($E$6:$E$50,"Target")
A55: Contacted | B55: A TWO-WAY exchange. A broadcast is not contact | Q55: =COUNTIF($E$6:$E$50,"Contacted")
A56: Visited | B56: You stood at his pump and the OWNER was there | Q56: =COUNTIF($E$6:$E$50,"Visited")
A57: Demoed | B57: Ten minutes on HIS customers and HIS rupee figures, decision-maker present (M06) | Q57: =COUNTIF($E$6:$E$50,"Demoed")
A58: Trial started | B58: Tenant created, balances entered, start and day-14 dates in his thread | Q58: =COUNTIF($E$6:$E$50,"Trial started")
A59: Paying | B59: Money received against a VSYST GST invoice | Q59: =COUNTIF($E$6:$E$50,"Paying")
A60: Activated (both sides) | B60: ≥1 customer firm linked AND ≥1 invoice within 14 days | Q60: =COUNTIF($E$6:$E$50,"Activated (both sides)")
A61: Referring | B61: A NAMED introduction that reached a two-way conversation | Q61: =COUNTIF($E$6:$E$50,"Referring")
A62: Lost | B62: A no, or a next date blank for 30 days. Reason recorded verbatim | Q62: =COUNTIF($E$6:$E$50,"Lost")
A64: C. Conversion math — computed off your own rows, then argued with
A65: Ratio | B65: Reached the earlier stage | C65: Reached the later stage | D65: Rate | E65: Benchmark | F65: Reading
A66: Demo → trial | B66: =COUNTIF($E$6:$E$50,"Demoed")+COUNTIF($E$6:$E$50,"Trial started")+COUNTIF($E$6:$E$50,"Paying")+COUNTIF($E$6:$E$50,"Activated (both sides)")+COUNTIF($E$6:$E$50,"Referring") | C66: =COUNTIF($E$6:$E$50,"Trial started")+COUNTIF($E$6:$E$50,"Paying")+COUNTIF($E$6:$E$50,"Activated (both sides)")+COUNTIF($E$6:$E$50,"Referring") | D66: =IF(B66=0,"",C66/B66) | E66: 40–50% (lesson 06 §1) | F66: Below it, the demo is not landing on his rupee figures.
A67: Demo → paying | B67: =COUNTIF($E$6:$E$50,"Demoed")+COUNTIF($E$6:$E$50,"Trial started")+COUNTIF($E$6:$E$50,"Paying")+COUNTIF($E$6:$E$50,"Activated (both sides)")+COUNTIF($E$6:$E$50,"Referring") | C67: =COUNTIF($E$6:$E$50,"Paying")+COUNTIF($E$6:$E$50,"Activated (both sides)")+COUNTIF($E$6:$E$50,"Referring") | D67: =IF(B67=0,"",C67/B67) | E67: ~32% SMB (Optifai) | F67: The headline number. Read it only past 20 demos.
A68: Trial → paying | B68: =COUNTIF($E$6:$E$50,"Trial started")+COUNTIF($E$6:$E$50,"Paying")+COUNTIF($E$6:$E$50,"Activated (both sides)")+COUNTIF($E$6:$E$50,"Referring") | C68: =COUNTIF($E$6:$E$50,"Paying")+COUNTIF($E$6:$E$50,"Activated (both sides)")+COUNTIF($E$6:$E$50,"Referring") | D68: =IF(B68=0,"",C68/B68) | E68: 35–45%; beat the unassisted 18.2% (First Page Sage) | F68: A trial nobody visits on day 14 converts like an unassisted one.
A69: Paying → activated | B69: =COUNTIF($E$6:$E$50,"Paying")+COUNTIF($E$6:$E$50,"Activated (both sides)")+COUNTIF($E$6:$E$50,"Referring") | C69: =COUNTIF($E$6:$E$50,"Activated (both sides)")+COUNTIF($E$6:$E$50,"Referring") | D69: =IF(B69=0,"",C69/B69) | E69: 60–75% — the rung marketing owns alone (HC10) | F69: Paying is not activated. Both sides live, or it does not count.
A70: Touches per win | C70: =COUNTIF($E$6:$E$50,"Paying")+COUNTIF($E$6:$E$50,"Activated (both sides)")+COUNTIF($E$6:$E$50,"Referring") | D70: =IF(C70=0,"",B70/C70) | E70: five (Cirrus Insight) | F70: Type the follow-ups you logged this quarter into B. If it is under three, you are quitting too early.
...

Sheet Marketing Scorecard
A1: Marketing Scorecard — the eight weekly numbers (HC8), thirteen weeks trailing
A2: Fills M13 §A. Eight rows, no more. One owner enters each number personally by Monday 09:30; the 09:40 huddle reads the sheet, never builds it. No metric without a source. Fill weeks left to right without gaps (Last = last filled week). Percentages as fractions (0.4 = 40%). Red two weeks running escalates automatically onto the COO's issues list at the 10:00 ops meeting. Goals and red lines are illustrative — VERIFY LIVE at quarterly planning.
H3: Week starting → | I3: 46265 | J3: =I3+7 | K3: =J3+7 | L3: =K3+7 | M3: =L3+7 | N3: =M3+7 | O3: =N3+7 | P3: =O3+7 | Q3: =P3+7 | ... U3: =T3+7
A4: # | B4: Metric (HC8) | C4: Owner | D4: Source | E4: Unit | F4: Direction | G4: Goal (Green) | H4: Red line | I4: W1 | J4: W2 | K4: W3 | L4: W4 | M4: W5 | N4: W6 | O4: W7 | P4: W8 | Q4: W9 | R4: W10 | S4: W11 | T4: W12 | U4: W13 | V4: Last | W4: Trend | X4: Status | Y4: Notes
A5: 1 | B5: Pump visits | C5: Domain dir. | D5: Pipeline tab — visits logged the same evening | E5: count | F5: Higher is better | G5: 8 | H5: 4 | I5: 9 | J5: 7 | K5: 12 | V5: =IF(COUNTA(I5:U5)=0,"",INDEX(I5:U5,1,COUNTA(I5:U5))) | W5: =IF(COUNTA(I5:U5)<2,"",IF(V5>INDEX(I5:U5,1,COUNTA(I5:U5)-1),"▲",IF(V5<INDEX(I5:U5,1,COUNTA(I5:U5)-1),"▼","►"))) | X5: =IF(V5="","",IF(F5="Higher is better",IF(V5>=G5,"Green",IF(V5<=H5,"Red","Amber")),IF(V5<=G5,"Green",IF(V5>=H5,"Red","Amber"))))
A6: 2 | B6: Demos done | C6: Domain dir. | D6: Pipeline tab, stage Demoed | E6: count | F6: Higher is better | G6: 5 | H6: 2 | I6: 2 | J6: 3 | K6: 4 | V6: =IF(COUNTA(I6:U6)=0,"",INDEX(I6:U6,1,COUNTA(I6:U6))) | W6: =IF(COUNTA(I6:U6)<2,"",IF(V6>INDEX(I6:U6,1,COUNTA(I6:U6)-1),"▲",IF(V6<INDEX(I6:U6,1,COUNTA(I6:U6)-1),"▼","►"))) | X6: =IF(V6="","",IF(F6="Higher is better",IF(V6>=G6,"Green",IF(V6<=H6,"Red","Amber")),IF(V6<=G6,"Green",IF(V6>=H6,"Red","Amber")))) | Y6: IS T05 row 2 — entered once here, read there.
A7: 3 | B7: Trials started | C7: Third dir. | D7: Mongo dealer_msts | E7: count | F7: Higher is better | G7: 3 | H7: 1 | I7: 1 | J7: 0 | K7: 2 | V7: =IF(COUNTA(I7:U7)=0,"",INDEX(I7:U7,1,COUNTA(I7:U7))) | W7: =IF(COUNTA(I7:U7)<2,"",IF(V7>INDEX(I7:U7,1,COUNTA(I7:U7)-1),"▲",IF(V7<INDEX(I7:U7,1,COUNTA(I7:U7)-1),"▼","►"))) | X7: =IF(V7="","",IF(F7="Higher is better",IF(V7>=G7,"Green",IF(V7<=H7,"Red","Amber")),IF(V7<=G7,"Green",IF(V7>=H7,"Red","Amber"))))
A8: 4 | B8: Dealers activated (≥1 customer linked + ≥1 invoice, 14 days) | C8: Third dir. | D8: Saved Mongo aggregation | E8: count | F8: Higher is better | G8: 2 | H8: 0 | V8: =IF(COUNTA(I8:U8)=0,"",INDEX(I8:U8,1,COUNTA(I8:U8))) | W8: =IF(COUNTA(I8:U8)<2,"",IF(V8>INDEX(I8:U8,1,COUNTA(I8:U8)-1),"▲",IF(V8<INDEX(I8:U8,1,COUNTA(I8:U8)-1),"▼","►"))) | X8: =IF(V8="","",IF(F8="Higher is better",IF(V8>=G8,"Green",IF(V8<=H8,"Red","Amber")),IF(V8<=G8,"Green",IF(V8>=H8,"Red","Amber")))) | Y8: Blank on purpose: aggregation not saved yet — CEO, this week. A blank with a reason beats a filled cell with a guess. IS T05 row 3.
A9: 5 | B9: Customers activated per activated dealer | C9: Third dir. | D9: dealer_custs × rate_msts | E9: ratio | F9: Higher is better | G9: 3 | H9: 1 | V9: =IF(COUNTA(I9:U9)=0,"",INDEX(I9:U9,1,COUNTA(I9:U9))) | W9: =IF(COUNTA(I9:U9)<2,"",IF(V9>INDEX(I9:U9,1,COUNTA(I9:U9)-1),"▲",IF(V9<INDEX(I9:U9,1,COUNTA(I9:U9)-1),"▼","►"))) | X9: =IF(V9="","",IF(F9="Higher is better",IF(V9>=G9,"Green",IF(V9<=H9,"Red","Amber")),IF(V9<=G9,"Green",IF(V9>=H9,"Red","Amber")))) | Y9: Same debt as row 4. Feeds T05 rows 4 and 5.
A10: 6 | B10: Referrals received | C10: Domain dir. | D10: Referral Tracker tab, M09 | E10: count | F10: Higher is better | G10: 2 | H10: 0 | I10: 0 | J10: 1 | K10: 1 | V10: =IF(COUNTA(I10:U10)=0,"",INDEX(I10:U10,1,COUNTA(I10:U10))) | W10: =IF(COUNTA(I10:U10)<2,"",IF(V10>INDEX(I10:U10,1,COUNTA(I10:U10)-1),"▲",IF(V10<INDEX(I10:U10,1,COUNTA(I10:U10)-1),"▼","►"))) | X10: =IF(V10="","",IF(F10="Higher is better",IF(V10>=G10,"Green",IF(V10<=H10,"Red","Amber")),IF(V10<=G10,"Green",IF(V10>=H10,"Red","Amber")))) | Y10: M13 states this row as 'asked / received', goal 5 / 2. One cell cannot RAG two numbers, so the scored number is RECEIVED; asks are counted on the Referral Tracker (goal 5, red 2) and read alongside.
A11: 7 | B11: WhatsApp reply rate | C11: Third dir. | D11: WhatsApp Business → Stats; replies within 48h ÷ recipients | E11: % | F11: Higher is better | G11: 0.4 | H11: 0.2 | I11: 0.31 | J11: 0.28 | K11: 0.4 | V11: =IF(COUNTA(I11:U11)=0,"",INDEX(I11:U11,1,COUNTA(I11:U11))) | W11: =IF(COUNTA(I11:U11)<2,"",IF(V11>INDEX(I11:U11,1,COUNTA(I11:U11)-1),"▲",IF(V11<INDEX(I11:U11,1,COUNTA(I11:U11)-1),"▼","►"))) | X11: =IF(V11="","",IF(F11="Higher is better",IF(V11>=G11,"Green",IF(V11<=H11,"Red","Amber")),IF(V11<=G11,"Green",IF(V11>=H11,"Red","Amber")))) | Y11: Computed on the Content Calendar tab.
A12: 8 | B12: CAC by channel — best channel, rolling 90 days | C12: CEO | D12: CAC & Payback tab | E12: ₹ | F12: Lower is better | G12: 8000 | H12: 20000 | V12: =IF(COUNTA(I12:U12)=0,"",INDEX(I12:U12,1,COUNTA(I12:U12))) | W12: =IF(COUNTA(I12:U12)<2,"",IF(V12>INDEX(I12:U12,1,COUNTA(I12:U12)-1),"▲",IF(V12<INDEX(I12:U12,1,COUNTA(I12:U12)-1),"▼","►"))) | X12: =IF(V12="","",IF(F12="Higher is better",IF(V12>=G12,"Green",IF(V12<=H12,"Red","Amber")),IF(V12<=G12,"Green",IF(V12>=H12,"Red","Amber")))) | Y12: The only lagging row; the seven above exist to move it. Blank until a channel has ≥3 paying dealers.
A14: Rules that make this sheet worth filling: eight rows, no more (HC8) — a ninth number means one of these eight is not earning its place. History is never overwritten; a wrong number is corrected in place with a note, not erased. On track / off track only at the huddle — the argument belongs at the 10:00 ops meeting. Rows 1–7 are controllable inputs you can move this week; row 8 is the lagging number they exist for. If a marketing number and a COO number disagree, CEO lesson 17 §6.6 wins and this sheet is wrong.

Sheet CAC & Payback
A1: CAC & Payback — what each channel cost per paying dealer, and how long it takes to earn back
A2: Fills M13 §B–D. One row per channel per quarter; never a row called 'marketing'. Founder hours are time-boxed and logged the same day — leave them out and the cheapest-looking channel is the one that ate 68 hours. Travel is kept separate so channels compare. A CAC is real at ≥3 paying dealers, not before. Every figure below is illustrative — VERIFY LIVE.
A4: A. House inputs — set once a year, never mid-quarter
A5: Input | B5: Value | C5: Unit | L5: How to set it honestly
A6: Imputed founder rate | B6: 400 | C6: ₹/hour | L6: (₹30,000 salary + ~₹8,000 travel/phone for the field associate we would hire instead) ÷ 22 days ÷ 8 h ≈ ₹216, DOUBLED because the founder also demos, prices and closes. House rule ₹400. VERIFY LIVE against Raipur associate comp (HC1). Move it at quarterly planning only, or CAC moves for reasons unrelated to marketing.
A7: MRR this month | B7: 10500 | C7: ₹ | L7: Billed and collected, ex-GST. Not signed, not promised.
A8: Paying GSTINs | B8: 7 | C8: count | L8: The billing unit. Users, staff and drivers are unlimited and free.
A9: ARPA (₹/month per paying GSTIN) | B9: =IF(B8=0,"",B7/B8) | C9: ₹ | L9: ≈ ₹1,500 ex-GST on a mid-skewed mix of ₹599 / ₹1,799 / ₹4,999 + Enterprise — VERIFY LIVE, owner sign-off pending.
A10: Gross margin | B10: 0.8 | C10: % | L10: (revenue − cost to serve) ÷ revenue. Cost to serve is OTP, hosting and support. 80% is the working assumption; CEO-Docs C12 owns the real number.
A11: Gross profit per dealer per month | B11: =IF(B9="","",B9*B10) | C11: ₹ | L11: ≈ ₹1,200. This is what actually pays back the acquisition — never use revenue.
A13: B. Spend by channel, this quarter — and what each dealer from it cost
A14: Channel | B14: Cash spend ₹ | C14: Founder hours | D14: Imputed founder cost ₹ | E14: Travel & fuel ₹ | F14: Total channel cost ₹ | G14: New paying dealers | H14: CAC ₹ | I14: Free months given | J14: Payback (months) | K14: Real yet? (≥3 dealers) | L14: Note
A15: Referral (Dealer Dost) | B15: 6000 | C15: 24 | D15: =IF(C15="","",C15*$B$6) | E15: 1250 | F15: =IF(COUNT(B15,D15,E15)=0,"",N(B15)+N(D15)+N(E15)) | G15: 3 | H15: =IF(OR(F15="",G15="",G15=0),"",F15/G15) | I15: 2 | J15: =IF(OR(H15="",$B$11="",$B$11=0),"",H15/$B$11+N(I15)) | K15: =IF(G15="","",IF(G15>=3,"Yes — decide on it","No — not a CAC yet")) | L15: ₹6,000 of bounties, 24 h of asks and follow-ups, ₹1,250 of travel. Two free months given, which cut gross profit — so they land on payback, not on CAC.
A16: OMC intro (IOCL territory manager) | B16: 2000 | C16: 68 | D16: =IF(C16="","",C16*$B$6) | E16: 3700 | F16: =IF(COUNT(B16,D16,E16)=0,"",N(B16)+N(D16)+N(E16)) | G16: 2 | H16: =IF(OR(F16="",G16="",G16=0),"",F16/G16) | I16: 0 | J16: =IF(OR(H16="",$B$11="",$B$11=0),"",H16/$B$11+N(I16)) | K16: =IF(G16="","",IF(G16>=3,"Yes — decide on it","No — not a CAC yet")) | L16: Almost entirely founder time. The relationship is real; the hours are the cost nobody writes down.
A17: Field visits (cold, in-cluster) | B17: 1000 | C17: 62 | D17: =IF(C17="","",C17*$B$6) | E17: 5600 | F17: =IF(COUNT(B17,D17,E17)=0,"",N(B17)+N(D17)+N(E17)) | G17: 2 | H17: =IF(OR(F17="",G17="",G17=0),"",F17/G17) | I17: 0 | J17: =IF(OR(H17="",$B$11="",$B$11=0),"",H17/$B$11+N(I17)) | K17: =IF(G17="","",IF(G17>=3,"Yes — decide on it","No — not a CAC yet")) | L17: The honest floor for walking in. Compare it against referral before you plan another week of it.
A18: Association / Dealer Day | D18: =IF(C18="","",C18*$B$6) | F18: =IF(COUNT(B18,D18,E18)=0,"",N(B18)+N(D18)+N(E18)) | H18: =IF(OR(F18="",G18="",G18=0),"",F18/G18) | J18: =IF(OR(H18="",$B$11="",$B$11=0),"",H18/$B$11+N(I18)) | K18: =IF(G18="","",IF(G18>=3,"Yes — decide on it","No — not a CAC yet"))
A19: CA / tax consultant | D19: =IF(C19="","",C19*$B$6) | F19: =IF(COUNT(B19,D19,E19)=0,"",N(B19)+N(D19)+N(E19)) | H19: =IF(OR(F19="",G19="",G19=0),"",F19/G19) | J19: =IF(OR(H19="",$B$11="",$B$11=0),"",H19/$B$11+N(I19)) | K19: =IF(G19="","",IF(G19>=3,"Yes — decide on it","No — not a CAC yet"))
A20: WhatsApp / content | D20: =IF(C20="","",C20*$B$6) | F20: =IF(COUNT(B20,D20,E20)=0,"",N(B20)+N(D20)+N(E20)) | H20: =IF(OR(F20="",G20="",G20=0),"",F20/G20) | J20: =IF(OR(H20="",$B$11="",$B$11=0),"",H20/$B$11+N(I20)) | K20: =IF(G20="","",IF(G20>=3,"Yes — decide on it","No — not a CAC yet"))
A21: Inbound (site, Play Store, GBP) | D21: =IF(C21="","",C21*$B$6) | F21: =IF(COUNT(B21,D21,E21)=0,"",N(B21)+N(D21)+N(E21)) | H21: =IF(OR(F21="",G21="",G21=0),"",F21/G21) | J21: =IF(OR(H21="",$B$11="",$B$11=0),"",H21/$B$11+N(I21)) | K21: =IF(G21="","",IF(G21>=3,"Yes — decide on it","No — not a CAC yet"))
A22: BLENDED — sanity check only, never a decision | B22: =SUM(B15:B21) | C22: =SUM(C15:C21) | D22: =SUM(D15:D21) | E22: =SUM(E15:E21) | F22: =SUM(F15:F21) | G22: =SUM(G15:G21) | H22: =IF(G22=0,"",F22/G22) | J22: =IF(OR(H22="",$B$11="",$B$11=0),"",H22/$B$11) | L22: Blended CAC moves when the MIX moves — a quarter with more referrals looks like a quarter where you got better at marketing. It cannot tell you which channel to feed.
A24: C. Monthly channel review — first Monday, 45 minutes, one verdict per channel
A25: Channel | B25: CAC ₹ | C25: × blended | D25: Paying dealers | E25: Payback (months) | F25: Suggested verdict | G25: Decided verdict | H25: Reason — required, written in the cell
A26: =A15 | B26: =H15 | C26: =IF(OR(H15="",$H$22="",$H$22=0),"",H15/$H$22) | D26: =G15 | E26: =J15 | F26: =IF(OR(H15="",G15=0),"no data yet",IF(H15>2*$H$22,"KILL candidate",IF(AND(H15<=$H$22,G15>=3),"SCALE candidate","KEEP")))
A27: =A16 | B27: =H16 | C27: =IF(OR(H16="",$H$22="",$H$22=0),"",H16/$H$22) | D27: =G16 | E27: =J16 | F27: =IF(OR(H16="",G16=0),"no data yet",IF(H16>2*$H$22,"KILL candidate",IF(AND(H16<=$H$22,G16>=3),"SCALE candidate","KEEP")))
A28: =A17 | B28: =H17 | C28: =IF(OR(H17="",$H$22="",$H$22=0),"",H17/$H$22) | D28: =G17 | E28: =J17 | F28: =IF(OR(H17="",G17=0),"no data yet",IF(H17>2*$H$22,"KILL candidate",IF(AND(H17<=$H$22,G17>=3),"SCALE candidate","KEEP")))
A29: =A18 | B29: =H18 | C29: =IF(OR(H18="",$H$22="",$H$22=0),"",H18/$H$22) | D29: =G18 | E29: =J18 | F29: =IF(OR(H18="",G18=0),"no data yet",IF(H18>2*$H$22,"KILL candidate",IF(AND(H18<=$H$22,G18>=3),"SCALE candidate","KEEP")))
A30: =A19 | B30: =H19 | C30: =IF(OR(H19="",$H$22="",$H$22=0),"",H19/$H$22) | D30: =G19 | E30: =J19 | F30: =IF(OR(H19="",G19=0),"no data yet",IF(H19>2*$H$22,"KILL candidate",IF(AND(H19<=$H$22,G19>=3),"SCALE candidate","KEEP")))
A31: =A20 | B31: =H20 | C31: =IF(OR(H20="",$H$22="",$H$22=0),"",H20/$H$22) | D31: =G20 | E31: =J20 | F31: =IF(OR(H20="",G20=0),"no data yet",IF(H20>2*$H$22,"KILL candidate",IF(AND(H20<=$H$22,G20>=3),"SCALE candidate","KEEP")))
A32: =A21 | B32: =H21 | C32: =IF(OR(H21="",$H$22="",$H$22=0),"",H21/$H$22) | D32: =G21 | E32: =J21 | F32: =IF(OR(H21="",G21=0),"no data yet",IF(H21>2*$H$22,"KILL candidate",IF(AND(H21<=$H$22,G21>=3),"SCALE candidate","KEEP")))
A34: The verdict rules — a verdict without a rule is a mood
A35: KILL | B35: Two months above 2× blended CAC with no improving trend. Write the reason in the cell: a killed channel with a reason can be revisited; one that quietly stopped cannot.
A36: KEEP | B36: At parity with blended. Nothing changes; it stays on the sheet.
A37: SCALE | B37: Two consecutive reviews beating blended AND ≥3 paying dealers from it. Raise capped at +50% of that line, one channel at a time. HC4's order still binds — no paid ads before ~50 dealers and a landing page with real proof.
A39: Reading the worked example: referral cost ₹16,850 for 3 dealers — CAC ₹5,617, payback 4.7 months, 6.7 after the two free months. The IOCL introduction cost ₹32,900 for 2 — CAC ₹16,450, payback 13.7. Cold field visits cost ₹31,400 for 2 — ₹15,700, payback 13.1. Blended is ₹81,150 ÷ 7 = ₹11,593, which flatters the expensive channels and punishes the cheap one. That is exactly why the decision is taken per channel. Bar for payback: CAC recovered under 12 months. Free months given are added to payback, never to CAC — they cut gross profit, not acquisition cost.

Sheet Campaign Budget
A1: Campaign Budget — one campaign on one page: brief, budget, weekly log, post-mortem, districts
A2: Fills M12. One brief per campaign, signed by all three founders before a rupee is spent. ONE number, X to Y by a date, and queryable. Founder time (~15 h/week × 3) sits OUTSIDE the cash budget and is stated so nobody calls the campaign free. Cash inside ₹30–50k/month while pre-revenue (HC7). Filled here with the Raipur 100 example — every figure illustrative.
A4: A. The one-page brief
A5: Field | B5: Fill
A6: Campaign name · ladder rung | B6: Raipur 100 · rung 2 (the founding ten → the district)
A7: Goal + THE one number | B7: Activated dealers 1 → 10 by the end of Week 12. Activated = ≥3 customer firms linked AND ≥1 invoice within 14 days. Query: CEO's saved Mongo aggregation over dealer_custs + invoices, run every Monday 09:00.
A8: Audience · list source | B8: The 100 named pumps within 60 km on the Target List tab, plus the credit customers each signed dealer names at onboarding.
A9: Message | B9: "पिछले महीने रेट को लेकर कितनी बहस हुई?" — fear of loss, a rupee number, and the dealer next door (HC5, M04).
A10: Offer | B10: 14-day no-card trial, on-site setup, ledger migration, founding-dealer listing. Price VERIFY LIVE — owner sign-off pending.
A11: Channels (1–2, in HC4 order) | B11: Referral → IOCL territory manager (Amey) → association → field visits. No paid ads on the dealer side before ~50 dealers.
A12: Budget | B12: ₹40,000/month × ~2.5 months ≈ ₹1.0 L cash. Founder time excluded and named: ~45 h/week across three founders ≈ ₹78,000/month imputed.
A13: Calendar by week · owners | B13: One row per week in section C; a founder's name on every row and every budget line.
A14: Risks · review cadence | B14: (1) Referrals dry up before the founding ten — watch asks per activated dealer. (2) The IOCL relationship stays social — watch written next steps. (3) Trials stall at day 14 — watch demo → trial. Cadence: Mon 09:30 numbers, Fri 18:00 learnings, mid-campaign kill/double, post-mortem within 5 days.
A15: Entry test passed? | B15: YES — dealer #1 both sides live, ≥1 invoice a week for four weeks. Evidence: his month-end, 31 Jul 2026. Without a measured pass of the rung below, nobody signs.
A17: B. The budget — every line carries a rupee figure and one name
A18: Line | B18: ₹ planned / month | C18: ₹ actual / month | D18: Variance ₹ | E18: Variance % | F18: Owner | G18: Cut order | H18: What it buys
A19: Fuel + travel (~8 visits/week, 60 km radius) | B19: 10000 | C19: 11500 | D19: =IF(OR(B19="",C19=""),"",C19-B19) | E19: =IF(OR(B19="",B19=0,C19=""),"",(C19-B19)/B19) | F19: Domain director | G19: 7th | H19: ~60 pump visits within 60 km
A20: Printing — leave-behind + GST/TCS booklet | B20: 6000 | C20: 5200 | D20: =IF(OR(B20="",C20=""),"",C20-B20) | E20: =IF(OR(B20="",B20=0,C20=""),"",(C20-B20)/B20) | F20: Third director | G20: 5th | H20: ~150 leaflets + 30 booklets
A21: Dealer Day / association (chai + CA session, 25–40 seats) | B21: 12000 | C21: 12000 | D21: =IF(OR(B21="",C21=""),"",C21-B21) | E21: =IF(OR(B21="",B21=0,C21=""),"",(C21-B21)/B21) | F21: Domain director | G21: 3rd | H21: A ₹24k event per quarter, amortised
A22: WhatsApp Business — BSP + templates, priced per DELIVERED message | B22: 4000 | C22: 3600 | D22: =IF(OR(B22="",C22=""),"",C22-B22) | E22: =IF(OR(B22="",B22=0,C22=""),"",(C22-B22)/B22) | F22: Third director | G22: 4th | H22: ~1,500 utility + ~500 marketing messages. ≈₹0.86 marketing / ₹0.115 utility + BSP markup + 18% GST — VERIFY LIVE
A23: Tools / software (CRM, design, landing page) | B23: 0 | C23: 0 | D23: =IF(OR(B23="",C23=""),"",C23-B23) | E23: =IF(OR(B23="",B23=0,C23=""),"",(C23-B23)/B23) | F23: Third director | G23: 2nd | H23: Free tiers until they break
A24: Referral payouts — Dealer Dost bounty accrual (2 × ₹2,000) | B24: 4000 | C24: 4000 | D24: =IF(OR(B24="",C24=""),"",C24-B24) | E24: =IF(OR(B24="",B24=0,C24=""),"",(C24-B24)/B24) | F24: Third director | G24: 8th — never cut | H24: The cheapest channel we have. Cut this last, or not at all
A25: Testimonial video (phone-shot + edit) | B25: 2000 | C25: 1500 | D25: =IF(OR(B25="",C25=""),"",C25-B25) | E25: =IF(OR(B25="",B25=0,C25=""),"",(C25-B25)/B25) | F25: CEO | G25: 6th | H25: One shoot, phone + freelance edit
A26: Contingency / channel experiment | B26: 2000 | C26: 3000 | D26: =IF(OR(B26="",C26=""),"",C26-B26) | E26: =IF(OR(B26="",B26=0,C26=""),"",(C26-B26)/B26) | F26: Third director | G26: 1st — cut first | H26: One Channel Experiments test
A27: TOTAL / month — must stay inside the ₹30–50k band (HC7) | B27: =SUM(B19:B26) | C27: =SUM(C19:C26) | D27: =C27-B27 | E27: =IF(B27=0,"",(C27-B27)/B27) | H27: Any single line moving by more than ₹5,000 needs a dated CEO sign-off and a line in the decision log. The envelope itself is a runway call.
A28: Founder time — NOT cash, never cut, always stated | B28: ≈₹78,000 | F28: All three | G28: — | H28: 45 h/week × ₹400 imputed. Roughly twice the cash budget: saving ₹5,000 of cash by spending ten extra founder hours is a losing trade.
A30: C. The weekly campaign log — filled Monday 09:30, zeros included
A31: Week | B31: Visits | C31: Demos | D31: Trials | E31: Activations | F31: Referrals | G31: Spend ₹ | H31: Learning (one line) | I31: Change made Monday
A32: W1
A33: W2
A34: W3
A35: W4
A36: W5
A37: W6 | B37: 9 | C37: 5 | D37: 2 | E37: 0 | F37: 1 | G37: 9400 | H37: Both cold walk-ins refused the demo; both introduced pumps sat through all ten minutes. | I37: Two cold-visit slots become referral asks.
A38: W7
A39: W8
A40: W9
A41: W10
A42: W11
A43: W12
...

Sheet Content Calendar
A1: Content Calendar — one piece a week, and whether it earned a reply
A2: Fills M11 §D. One row, one piece, forty minutes of editing: four hours means the format is wrong. Row filled Friday, broadcast Tuesday. Never Sunday; 10:30–12:30 or 16:00–18:00, outside the pump's rush. One broadcast per list per week, maximum — and only to dealers who opted in AND saved your number. Reply rate here is scorecard row 7. Zero replies twice means the row is deleted, not debated.
A4: A. The calendar
A5: Week | B5: Piece | C5: Type | D5: Persona | E5: Shoot owner | F5: Edit owner | G5: Channels (Status → broadcast → Shorts → GBP → LinkedIn) | H5: Posted ✓ | I5: Recipients | J5: Replies @48h | K5: Reply rate | L5: Views @48h | M5: Reuse | N5: Verdict
A6: W1 | B6: "3 din se 10 minute" — Sharma ji | C6: Testimonial, 84s | D6: Owner, 52 | E6: Domain dir | F6: Third dir | G6: Status, broadcast, Shorts, GBP | H6: ✓ | I6: 34 | J6: 7 | K6: =IF(OR(I6="",I6=0),"",J6/I6) | L6: 260 | M6: Still + pull-quote for the leave-behind | N6: keep
A7: W2 | B7: "Month-end in 10 minutes" | C7: Screen recording, 110s | D7: Accountant | E7: Third dir | F7: Third dir | G7: Status, broadcast, Shorts | H7: ✓ | I7: 34 | J7: 3 | K7: =IF(OR(I7="",I7=0),"",J7/I7) | L7: 190 | M7: Three-line text for WhatsApp openers | N7: kill
A8: W3 | B8: "जो रेट तय हुआ था" | C8: Story, 62s | D8: Owner + son | E8: Domain dir | F8: Third dir | G8: Status, broadcast, Shorts, GBP | H8: ✓ | I8: 36 | J8: 9 | K8: =IF(OR(I8="",I8=0),"",J8/I8) | L8: 410 | M8: Landing-page paragraph + proof slot 2 | N8: keep
A9: W4 | B9: "TCS ₹50L ke baad", with CA Bhatia | C9: Explainer with CA, 118s | D9: Son / accountant | E9: Third dir | F9: Third dir | G9: Status, broadcast, Shorts, LinkedIn | H9: ✓ | I9: 36 | J9: 4 | K9: =IF(OR(I9="",I9=0),"",J9/I9) | L9: 150 | M9: Warm-up asset for the CA partner playbook, not a broadcast | N9: kill
A10: W5 | K10: =IF(OR(I10="",I10=0),"",J10/I10)
A11: W6 | K11: =IF(OR(I11="",I11=0),"",J11/I11)
A12: W7 | K12: =IF(OR(I12="",I12=0),"",J12/I12)
A13: W8 | K13: =IF(OR(I13="",I13=0),"",J13/I13)
A14: W9 | K14: =IF(OR(I14="",I14=0),"",J14/I14)
A15: W10 | K15: =IF(OR(I15="",I15=0),"",J15/I15)
A16: W11 | K16: =IF(OR(I16="",I16=0),"",J16/I16)
A17: W12 | K17: =IF(OR(I17="",I17=0),"",J17/I17)
A18: W13 | K18: =IF(OR(I18="",I18=0),"",J18/I18)
A19: W14 | K19: =IF(OR(I19="",I19=0),"",J19/I19)
A20: W15 | K20: =IF(OR(I20="",I20=0),"",J20/I20)
A21: W16 | K21: =IF(OR(I21="",I21=0),"",J21/I21)
... A31: W26 | K31: =IF(OR(I31="",I31=0),"",J31/I31)
A33: B. Rows that go to the Marketing Scorecard and the campaign post-mortem
A34: Row | B34: Formula | C34: Value | D34: Goal | E34: Cadence
A35: WhatsApp reply rate (rolling, all filled weeks) | B35: Σ replies ÷ Σ recipients — never the average of the weekly percentages | C35: =IF(SUM(I6:I31)=0,"",SUM(J6:J31)/SUM(I6:I31)) | D35: 0.15 | E35: Weekly — one of HC8's eight, scorecard row 7
A36: Pieces published | B36: Rows marked Posted ✓ | C36: =COUNTIF(H6:H31,"✓") | D36: 1 | E36: Weekly, hygiene — one a week, forever
A37: Median views @48h | B37: Vanity on its own; useful only next to replies | C37: =IF(COUNT(L6:L31)=0,"",MEDIAN(L6:L31)) | E37: Monthly, context only
A38: Click-to-chat conversion | B38: Chats opened ÷ page visits — hand-counted on Friday from the inbox; GA4 sees the click, only the inbox sees the conversation | D38: 0.05 | E38: Monthly, into the campaign post-mortem
A40: C. The broadcast rules — break one and the number your pipeline lives in gets banned
A41: Rule | B41: What it says
A42: Opt-in | B42: Before any broadcast. The line must say the person agrees to receive messages AND name the business. A tick on the pump-visit form or on the site both count.
A43: Saved your number | B43: A broadcast reaches only people who saved your number. They receive nothing otherwise — and you conclude, wrongly, that the channel is dead.
A44: Cadence | B44: One per list per week, maximum. Never Sunday; 10:30–12:30 or 16:00–18:00.
A45: Shape | B45: Proof → one line → one tap. Five lines or fewer, one link, one action.
A46: Reply SLA | B46: Two working hours between 09:00 and 20:00; one working day always. A broadcast you do not staff is worse than none.
A47: List size | B47: One list, ≤256 dealers. When it outgrows the app — the same message to 200+ dealers, or a second list — that is the trigger for the API, and only then.
A48: UTMs | B48: utm_source, utm_medium, utm_campaign on every outbound link. House form: ?utm_source=whatsapp&utm_medium=broadcast&utm_campaign=raipur100-w07
A49: The CTA | B49: A chat, not a form. wa.me/91XXXXXXXXXX?text=<url-encoded first line> — international format, no zeroes, brackets or dashes. Nobody in this market fills a form.
A51: Reading the four example weeks: the story-shaped pieces out-pull the explanatory ones two to one, so W5–W8 become dealer stories from other tehsils and the CA explainer survives as a partner warm-up, not a broadcast. Rolling reply rate 16.4% clears the ≥15% goal; click-to-chat 4.6% falls just short. Founder time for the month: five hours. Count replies by hand — the free WhatsApp Business app has no dashboard. India WhatsApp pricing ≈ ₹0.86 per marketing message, ₹0.115 per utility, + BSP markup ₹0.10–0.30 + 18% GST — VERIFY LIVE with the BSP.

Sheet Referral Tracker
A1: Referral Tracker — every Dealer Dost ask, including the ones that failed
A2: Fills M09 §C. One row per REFERRED PUMP, never 'two names given'. Logged the same day, always — even if he said no. Reviewed Friday, 30 minutes. The ask is made at the activation moment, never at the sale, and never in the first 14 days. Ask only for the two pumps he already talks to. Reward on payment, not signup — the strongest anti-fraud lever there is. All rupee figures VERIFY LIVE against the signed tier sheet.
A4: A. The tracker
A5: Referrer (dealer + pump) | B5: Referred pump (name, owner, place) | C5: Date asked | D5: Date received | E5: Stage | F5: Reward due ₹ | G5: Paid on | H5: UTR | I5: Owner (ours) | J5: Note
A6: Sharma ji — Dhamtari Road Fuels | B6: HP outlet, Tatibandh — owner N. Chandrakar | C6: 46255 | D6: 46255 | E6: Name received | F6: =IF(E6="","",IF(E6="Paying",5000,IF(E6="Live",2000,0))) | I6: Domain dir. | J6: Three-way WhatsApp group made on the spot. Next step Monday.
A7: Sharma ji — Dhamtari Road Fuels | B7: Cousin's pump, Abhanpur — owner P. Sharma | C7: 46255 | D7: 46255 | E7: Name received | F7: =IF(E7="","",IF(E7="Paying",5000,IF(E7="Live",2000,0))) | I7: Domain dir. | J7: Forwarded our message. Meeting not yet agreed.
A8: R. Verma — Maa Danteshwari Fuels | B8: Kharora highway pump — owner S. Sahu | C8: 46217 | D8: 46219 | E8: Live | F8: =IF(E8="","",IF(E8="Paying",5000,IF(E8="Live",2000,0))) | I8: Domain dir. | J8: Went live on one outlet 12 Aug. First ₹2,000 due — CEO to sign the payout.
A9: R. Verma — Maa Danteshwari Fuels | B9: Mandir Hasaud pump — owner A. Yadav | C9: 46203 | D9: 46205 | E9: Paying | F9: =IF(E9="","",IF(E9="Paying",5000,IF(E9="Live",2000,0))) | G9: 46254 | H9: UTR 2026082012345678 | I9: Domain dir. | J9: Month-3 payment received. Full ₹5,000 paid.
A10: M. Agrawal — Shree Balaji Filling | B10: Birgaon pump — owner (name not given) | C10: 46246 | E10: Asked | F10: =IF(E10="","",IF(E10="Paying",5000,IF(E10="Live",2000,0))) | I10: CEO | J10: Said he would think about it. Logged anyway — the failures are the honest half of the sheet.
F11: =IF(E11="","",IF(E11="Paying",5000,IF(E11="Live",2000,0)))
F12: =IF(E12="","",IF(E12="Paying",5000,IF(E12="Live",2000,0)))
F13: =IF(E13="","",IF(E13="Paying",5000,IF(E13="Live",2000,0)))
F14: =IF(E14="","",IF(E14="Paying",5000,IF(E14="Live",2000,0)))
F15: =IF(E15="","",IF(E15="Paying",5000,IF(E15="Live",2000,0)))
F16: =IF(E16="","",IF(E16="Paying",5000,IF(E16="Live",2000,0)))
F17: =IF(E17="","",IF(E17="Paying",5000,IF(E17="Live",2000,0)))
F18: =IF(E18="","",IF(E18="Paying",5000,IF(E18="Live",2000,0)))
F19: =IF(E19="","",IF(E19="Paying",5000,IF(E19="Live",2000,0)))
F20: =IF(E20="","",IF(E20="Paying",5000,IF(E20="Live",2000,0)))
F21: =IF(E21="","",IF(E21="Paying",5000,IF(E21="Live",2000,0)))
F22: =IF(E22="","",IF(E22="Paying",5000,IF(E22="Live",2000,0)))
... F40: =IF(E40="","",IF(E40="Paying",5000,IF(E40="Live",2000,0)))
A42: B. Totals — read every Friday, 30 minutes
A43: Count / amount | B43: Value | C43: Rule
A44: Asks made (rows logged) | B44: =SUMPRODUCT(1*(A6:A40<>"")) | C44: Every ask, including the ones that went nowhere. Scorecard: referrals asked, goal 5/week.
A45: Names received | B45: =SUMPRODUCT(1*(D6:D40<>"")) | C45: A name is not a referral. Scorecard row 6 counts what actually arrived.
A46: Meetings agreed | B46: =COUNTIF(E6:E40,"Meeting agreed") | C46: This is where a name becomes a referral — the owner agreed to meet us.
A47: Live | B47: =COUNTIF(E6:E40,"Live") | C47: First bounty falls due here: ₹2,000 on go-live at one outlet. VERIFY LIVE.
A48: Paying (month 3) | B48: =COUNTIF(E6:E40,"Paying") | C48: Second bounty falls due: a further ₹3,000, ₹5,000 in total. VERIFY LIVE.
A49: Ask → name conversion | B49: =IF(SUMPRODUCT(1*(A6:A40<>""))=0,"",SUMPRODUCT(1*(D6:D40<>""))/SUMPRODUCT(1*(A6:A40<>""))) | C49: Under 50% usually means the ask was generic. Never 'do you know anyone?' — ask for the two pumps he already talks to.
A50: Total reward due ₹ | B50: =SUM(F6:F40) | C50: Accrue it in the campaign budget the moment a row goes Live, not when it is paid.
A51: Total paid ₹ | B51: =SUMIFS(F6:F40,G6:G40,">0") | C51: Paid means a UTR is in the row. No UTR, not paid.
A52: Outstanding ₹ | B52: =B50-B51 | C52: What we owe dealers right now. A withdrawn or delayed reward costs more trust than it bought.
A53: Largest single referrer, ₹ this FY | B53: =IF(COUNTA(A6:A40)=0,"",MAX(SUMIF(A6:A40,A6:A40,F6:F40))) | C53: Array formula — confirm with Ctrl+Shift+Enter in older Excel. TDS at 10% under §194R can apply once benefits to ONE recipient cross ₹20,000 in a financial year. The CA signs off before the first payout. VERIFY LIVE.
A55: C. The ask — say it, do not send it
A56: Moment | B56: What you open with | C56: What you ask for
A57: First clean month-end | B57: "Sir, is mahine month-end saaf nikla — koi ledger ka jhagda nahi." | C57: The two pumps he already talks to, by name
A58: First dispute avoided | B58: "Wo rate wali baat OTP se ek minute mein khatam ho gayi na?" | C58: The same two names
A59: Unprompted praise | B59: Stop the conversation right there | C59: The same two names
A60: NEVER | B60: At the sale, or in the first 14 days | C60: —
...

Sheet Channel Experiments
A1: Channel Experiments — one channel, two weeks, one number, a verdict
A2: Fills lesson 05 §6 and exercise 10.3; reviewed monthly per lesson 11 §7. Exactly one channel per row — two at once teach nothing about either. The kill line is written BEFORE the start date and the verdict cell stays empty until the end date, which goes in the calendar as a 15-minute meeting named 'Verdict: <channel>'. Two weeks is deliberate: long enough for an association meeting or a CA callback, short enough that a bad channel costs a fortnight.
A4: A. The experiments
A5: Channel | B5: Hypothesis (one falsifiable sentence) | C5: Start | D5: End (+14 days) | E5: Founder hours | F5: Cash spend ₹ | G5: Travel ₹ | H5: Total cost ₹ | I5: The number counted | J5: Kill line (written before the start) | K5: Contacts | L5: Demos | M5: Paying dealers | N5: CAC ₹ | O5: Verdict | P5: Owner | Q5: Notes / why
A6: CA / tax consultant | B6: A Raipur CA with pump clients introduces 3+ dealers for a 10% revenue share. | C6: 46266 | D6: 46280 | E6: 6 | F6: 2000 | G6: 800 | H6: =IF(COUNT(E6,F6,G6)=0,"",N(F6)+N(E6)*'CAC & Payback'!$B$6+N(G6)) | I6: Qualified pump meetings booked | J6: <2 meetings in 14 days → kill | K6: 5 | L6: 2 | M6: 1 | N6: =IF(OR(H6="",M6="",M6=0),"—",H6/M6) | O6: keep | P6: Third dir. | Q6: Five CAs met, two introduced someone. Slow, but the introduction is warm and the accountant is the objection we hear most.
A7: Dealer association (district) | B7: The district association lets us run a 30-minute GST/TCS session at a members' meeting, and 3+ owners ask for a demo. | C7: 46281 | D7: 46295 | E7: 10 | F7: 8000 | G7: 1200 | H7: =IF(COUNT(E7,F7,G7)=0,"",N(F7)+N(E7)*'CAC & Payback'!$B$6+N(G7)) | I7: Demo requests from attendees | J7: <3 demo requests → kill | K7: 28 | L7: 4 | M7: 1 | N7: =IF(OR(H7="",M7="",M7=0),"—",H7/M7) | O7: keep | P7: Domain dir. | Q7: Office-bearer's name came from the live dealer. One session per quarter, not one per month.
A8: WhatsApp community | B8: Being useful in two existing dealer groups produces 2+ inbound conversations in 14 days. | C8: 46296 | D8: 46310 | E8: 8 | F8: 0 | G8: 0 | H8: =IF(COUNT(E8,F8,G8)=0,"",N(F8)+N(E8)*'CAC & Payback'!$B$6+N(G8)) | I8: Inbound two-way conversations | J8: <2 conversations → kill | K8: 3 | L8: 1 | M8: 0 | N8: =IF(OR(H8="",M8="",M8=0),"—",H8/M8) | O8: kill | P8: Third dir. | Q8: Killed with a reason: the groups are for rates and complaints, not tools. Revisit only with a dealer vouching in the group.
A9: Hardware service engineers | B9: Pump automation engineers, who visit every pump quarterly, will name 5+ automated pumps for a referral fee. | C9: 46311 | D9: 46325 | E9: 5 | F9: 1500 | G9: 900 | H9: =IF(COUNT(E9,F9,G9)=0,"",N(F9)+N(E9)*'CAC & Payback'!$B$6+N(G9)) | I9: Named, automated pumps handed over | J9: <5 names in 14 days → kill | K9: 2 | L9: 0 | M9: 0 | N9: =IF(OR(H9="",M9="",M9=0),"—",H9/M9) | P9: Domain dir. | Q9: Running. Verdict meeting is in the calendar for the end date.
H10: =IF(COUNT(E10,F10,G10)=0,"",N(F10)+N(E10)*'CAC & Payback'!$B$6+N(G10)) | N10: =IF(OR(H10="",M10="",M10=0),"—",H10/M10)
H11: =IF(COUNT(E11,F11,G11)=0,"",N(F11)+N(E11)*'CAC & Payback'!$B$6+N(G11)) | N11: =IF(OR(H11="",M11="",M11=0),"—",H11/M11)
H12: =IF(COUNT(E12,F12,G12)=0,"",N(F12)+N(E12)*'CAC & Payback'!$B$6+N(G12)) | N12: =IF(OR(H12="",M12="",M12=0),"—",H12/M12)
H13: =IF(COUNT(E13,F13,G13)=0,"",N(F13)+N(E13)*'CAC & Payback'!$B$6+N(G13)) | N13: =IF(OR(H13="",M13="",M13=0),"—",H13/M13)
H14: =IF(COUNT(E14,F14,G14)=0,"",N(F14)+N(E14)*'CAC & Payback'!$B$6+N(G14)) | N14: =IF(OR(H14="",M14="",M14=0),"—",H14/M14)
H15: =IF(COUNT(E15,F15,G15)=0,"",N(F15)+N(E15)*'CAC & Payback'!$B$6+N(G15)) | N15: =IF(OR(H15="",M15="",M15=0),"—",H15/M15)
H16: =IF(COUNT(E16,F16,G16)=0,"",N(F16)+N(E16)*'CAC & Payback'!$B$6+N(G16)) | N16: =IF(OR(H16="",M16="",M16=0),"—",H16/M16)
H17: =IF(COUNT(E17,F17,G17)=0,"",N(F17)+N(E17)*'CAC & Payback'!$B$6+N(G17)) | N17: =IF(OR(H17="",M17="",M17=0),"—",H17/M17)
H18: =IF(COUNT(E18,F18,G18)=0,"",N(F18)+N(E18)*'CAC & Payback'!$B$6+N(G18)) | N18: =IF(OR(H18="",M18="",M18=0),"—",H18/M18)
H19: =IF(COUNT(E19,F19,G19)=0,"",N(F19)+N(E19)*'CAC & Payback'!$B$6+N(G19)) | N19: =IF(OR(H19="",M19="",M19=0),"—",H19/M19)
H20: =IF(COUNT(E20,F20,G20)=0,"",N(F20)+N(E20)*'CAC & Payback'!$B$6+N(G20)) | N20: =IF(OR(H20="",M20="",M20=0),"—",H20/M20)
H21: =IF(COUNT(E21,F21,G21)=0,"",N(F21)+N(E21)*'CAC & Payback'!$B$6+N(G21)) | N21: =IF(OR(H21="",M21="",M21=0),"—",H21/M21)
... H29: =IF(COUNT(E29,F29,G29)=0,"",N(F29)+N(E29)*'CAC & Payback'!$B$6+N(G29)) | N29: =IF(OR(H29="",M29="",M29=0),"—",H29/M29)
A31: B. The method — six fields, and the sixth is written last
A32: Field | B32: Rule
A33: Channel | B33: Exactly one. Two at once teach nothing about either.
A34: Hypothesis | B34: One falsifiable sentence, with a number in it. If it cannot be wrong, it is not a hypothesis.
A35: Effort box | B35: Hours and rupees, fixed up front. When the box is empty the experiment ends, whatever the result looks like.
A36: The number | B36: One, and a step you control — meetings booked, names handed over. Never revenue.
A37: Kill line | B37: Written BEFORE you start. Writing it afterwards is how a dead channel survives six months.
A38: Verdict | B38: Kill / keep / scale, with one sentence of why. A killed channel with a reason can be revisited; one that quietly stopped cannot.
A40: C. The channel order (HC4) — and what is not open yet
A41: # | B41: Channel | C41: Status today | D41: Trigger to open it
A42: 1 | B42: Referral (Dealer Dost) | C42: OPEN — channel one, cheapest we have | D42: Already open. Ask at every activation moment.
A43: 2 | B43: OMC territory manager / IOCL relationship | C43: OPEN — live conversation via Amey | D43: Already open. One meeting a month, with a written next step each time.
A44: 3 | B44: Dealer association | C44: OPEN | D44: Already open. One session a quarter.
A45: 4 | B45: CA / tax consultant | C45: OPEN — under test | D45: Already open. See the experiment rows above.
A46: 5 | B46: Field visits | C46: OPEN — the honest floor | D46: Already open, and the most expensive thing on the sheet. Compare it against referral every month.
A47: 6 | B47: WhatsApp community | C47: TESTED — killed with a reason | D47: A live dealer willing to vouch inside the group.
A48: 7 | B48: Content / SEO | C48: NOT YET | D48: Three real dealer proofs and a landing page that converts a chat. Months, not weeks.
A49: 8 | B49: Paid ads | C49: NOT YET — HC4 is explicit | D49: ~50 paying dealers AND a landing page with real proof. CEO decides, in writing.
A50: 9 | B50: Cold email / LinkedIn | C50: NOT YET — narrow | D50: Second-generation owners only. Never the 55-year-old signer.
...
